python3: can't open file 'boy.py': [Errno 2] No such file or directory
python3: can't open file 'boy.py': [Errno 2] No such file or directory
python3: can't open file 'boy.py': [Errno 2] No such file or directory
Future exception was never retrieved
future: <Future finished exception=Exception('이미 채널에 해당 계정이 추가 되어 있습니다.')>
Traceback (most recent call last):
  File "/usr/lib/python3.7/concurrent/futures/thread.py", line 57, in run
    result = self.fn(*self.args, **self.kwargs)
  File "/home/pi/Likesbot/getpic.py", line 167, in _add
    self.data.add_channel_user(channel_id, self.data.get_user_id(screen_name))
  File "/home/pi/Likesbot/getpic.py", line 128, in add_channel_user
    raise Exception("이미 채널에 해당 계정이 추가 되어 있습니다.")
Exception: 이미 채널에 해당 계정이 추가 되어 있습니다.
Traceback (most recent call last):
  File "/usr/lib/python3/dist-packages/urllib3/connection.py", line 159, in _new_conn
    (self._dns_host, self.port), self.timeout, **extra_kw)
  File "/usr/lib/python3/dist-packages/urllib3/util/connection.py", line 57, in create_connection
    for res in socket.getaddrinfo(host, port, family, socket.SOCK_STREAM):
  File "/usr/lib/python3.7/socket.py", line 748, in getaddrinfo
    for res in _socket.getaddrinfo(host, port, family, type, proto, flags):
socket.gaierror: [Errno -3] Temporary failure in name resolution

During handling of the above exception, another exception occurred:

Traceback (most recent call last):
  File "/usr/lib/python3/dist-packages/urllib3/connectionpool.py", line 600, in urlopen
    chunked=chunked)
  File "/usr/lib/python3/dist-packages/urllib3/connectionpool.py", line 354, in _make_request
    conn.request(method, url, **httplib_request_kw)
  File "/usr/lib/python3.7/http/client.py", line 1229, in request
    self._send_request(method, url, body, headers, encode_chunked)
  File "/usr/lib/python3.7/http/client.py", line 1275, in _send_request
    self.endheaders(body, encode_chunked=encode_chunked)
  File "/usr/lib/python3.7/http/client.py", line 1224, in endheaders
    self._send_output(message_body, encode_chunked=encode_chunked)
  File "/usr/lib/python3.7/http/client.py", line 1016, in _send_output
    self.send(msg)
  File "/usr/lib/python3.7/http/client.py", line 956, in send
    self.connect()
  File "/usr/lib/python3/dist-packages/urllib3/connection.py", line 181, in connect
    conn = self._new_conn()
  File "/usr/lib/python3/dist-packages/urllib3/connection.py", line 168, in _new_conn
    self, "Failed to establish a new connection: %s" % e)
urllib3.exceptions.NewConnectionError: <urllib3.connection.HTTPConnection object at 0x7484cf90>: Failed to establish a new connection: [Errno -3] Temporary failure in name resolution

During handling of the above exception, another exception occurred:

Traceback (most recent call last):
  File "/usr/lib/python3/dist-packages/requests/adapters.py", line 449, in send
    timeout=timeout
  File "/usr/lib/python3/dist-packages/urllib3/connectionpool.py", line 638, in urlopen
    _stacktrace=sys.exc_info()[2])
  File "/usr/lib/python3/dist-packages/urllib3/util/retry.py", line 398, in increment
    raise MaxRetryError(_pool, url, error or ResponseError(cause))
urllib3.exceptions.MaxRetryError: HTTPConnectionPool(host='skyrich3.synology.me', port=80): Max retries exceeded with url: /~Huni/likesbot/loadnum.txt (Caused by NewConnectionError('<urllib3.connection.HTTPConnection object at 0x7484cf90>: Failed to establish a new connection: [Errno -3] Temporary failure in name resolution'))

During handling of the above exception, another exception occurred:

Traceback (most recent call last):
  File "bot.py", line 2, in <module>
    import getpic
  File "/home/pi/Likesbot/getpic.py", line 10, in <module>
    LoadNum = int(requests.get("http://skyrich3.synology.me/~Huni/likesbot/loadnum.txt").text)
  File "/usr/lib/python3/dist-packages/requests/api.py", line 75, in get
    return request('get', url, params=params, **kwargs)
  File "/usr/lib/python3/dist-packages/requests/api.py", line 60, in request
    return session.request(method=method, url=url, **kwargs)
  File "/usr/lib/python3/dist-packages/requests/sessions.py", line 533, in request
    resp = self.send(prep, **send_kwargs)
  File "/usr/lib/python3/dist-packages/requests/sessions.py", line 646, in send
    r = adapter.send(request, **kwargs)
  File "/usr/lib/python3/dist-packages/requests/adapters.py", line 516, in send
    raise ConnectionError(e, request=request)
requests.exceptions.ConnectionError: HTTPConnectionPool(host='skyrich3.synology.me', port=80): Max retries exceeded with url: /~Huni/likesbot/loadnum.txt (Caused by NewConnectionError('<urllib3.connection.HTTPConnection object at 0x7484cf90>: Failed to establish a new connection: [Errno -3] Temporary failure in name resolution'))
